<?xml version="1.0" ?>
<!-- =================================================================================== -->
<!-- |    This document was autogenerated by xacro from src/simulation/urdf/xacro_gazebo/car_gazebo.xacro | -->
<!-- |    EDITING THIS FILE BY HAND IS NOT RECOMMENDED                                 | -->
<!-- =================================================================================== -->
<!-- 组合小车底盘与摄像头 -->
<robot name="my_car_camera">
  <!-- 宏:黑色设置 -->
  <material name="black">
    <color rgba="0.0 0.0 0.0 1.0"/>
  </material>
  <!-- 质量  -->
  <!-- 底盘 -->
  <link name="base_footprint">
    <visual>
      <geometry>
        <sphere radius="0.001"/>
      </geometry>
    </visual>
  </link>
  <link name="base_link">
    <visual>
      <geometry>
        <cylinder length="0.08" radius="0.1"/>
      </geometry>
      <origin rpy="0 0 0" xyz="0 0 0"/>
      <material name="yellow">
        <color rgba="0.5 0.3 0.0 0.5"/>
      </material>
    </visual>
    <collision>
      <geometry>
        <cylinder length="0.08" radius="0.1"/>
      </geometry>
      <origin rpy="0 0 0" xyz="0 0 0"/>
    </collision>
    <inertial>
      <mass value="0.5"/>
      <inertia ixx="0.001516666666666667" ixy="0" ixz="0" iyy="0.001516666666666667" iyz="0" izz="0.0025000000000000005"/>
    </inertial>
  </link>
  <joint name="base_link2base_footprint" type="fixed">
    <parent link="base_footprint"/>
    <child link="base_link"/>
    <origin xyz="0 0 0.055"/>
  </joint>
  <gazebo reference="base_link">
    <material>Gazebo/Yellow</material>
  </gazebo>
  <!-- 质量  -->
  <link name="left_wheel">
    <visual>
      <geometry>
        <cylinder length="0.015" radius="0.0325"/>
      </geometry>
      <origin rpy="1.5707963 0.0 0.0" xyz="0.0 0.0 0.0"/>
      <material name="black"/>
    </visual>
    <collision>
      <geometry>
        <cylinder length="0.015" radius="0.0325"/>
      </geometry>
      <origin rpy="1.5707963 0.0 0.0" xyz="0.0 0.0 0.0"/>
    </collision>
    <inertial>
      <mass value="0.05"/>
      <inertia ixx="1.4140625000000002e-05" ixy="0" ixz="0" iyy="1.4140625000000002e-05" iyz="0" izz="2.6406250000000005e-05"/>
    </inertial>
  </link>
  <joint name="left_wheel2base_link" type="continuous">
    <parent link="base_link"/>
    <child link="left_wheel"/>
    <origin xyz="0 0.1 -0.0225"/>
    <axis xyz="0 1 0"/>
  </joint>
  <gazebo reference="left_wheel">
    <material>Gazebo/Red</material>
  </gazebo>
  <link name="right_wheel">
    <visual>
      <geometry>
        <cylinder length="0.015" radius="0.0325"/>
      </geometry>
      <origin rpy="1.5707963 0.0 0.0" xyz="0.0 0.0 0.0"/>
      <material name="black"/>
    </visual>
    <collision>
      <geometry>
        <cylinder length="0.015" radius="0.0325"/>
      </geometry>
      <origin rpy="1.5707963 0.0 0.0" xyz="0.0 0.0 0.0"/>
    </collision>
    <inertial>
      <mass value="0.05"/>
      <inertia ixx="1.4140625000000002e-05" ixy="0" ixz="0" iyy="1.4140625000000002e-05" iyz="0" izz="2.6406250000000005e-05"/>
    </inertial>
  </link>
  <joint name="right_wheel2base_link" type="continuous">
    <parent link="base_link"/>
    <child link="right_wheel"/>
    <origin xyz="0 -0.1 -0.0225"/>
    <axis xyz="0 1 0"/>
  </joint>
  <gazebo reference="right_wheel">
    <material>Gazebo/Red</material>
  </gazebo>
  <!-- 质量  -->
  <link name="front_wheel">
    <visual>
      <geometry>
        <sphere radius="0.0075"/>
      </geometry>
      <origin rpy="0 0 0" xyz="0 0 0"/>
      <material name="black"/>
    </visual>
    <collision>
      <geometry>
        <sphere radius="0.0075"/>
      </geometry>
      <origin rpy="0 0 0" xyz="0 0 0"/>
    </collision>
    <inertial>
      <mass value="0.03"/>
      <inertia ixx="6.75e-07" ixy="0" ixz="0" iyy="6.75e-07" iyz="0" izz="6.75e-07"/>
    </inertial>
  </link>
  <joint name="front_wheel2base_link" type="continuous">
    <parent link="base_link"/>
    <child link="front_wheel"/>
    <origin xyz="0.0925 0 -0.0475"/>
    <axis xyz="1 1 1"/>
  </joint>
  <gazebo reference="front_wheel">
    <material>Gazebo/Red</material>
  </gazebo>
  <link name="back_wheel">
    <visual>
      <geometry>
        <sphere radius="0.0075"/>
      </geometry>
      <origin rpy="0 0 0" xyz="0 0 0"/>
      <material name="black"/>
    </visual>
    <collision>
      <geometry>
        <sphere radius="0.0075"/>
      </geometry>
      <origin rpy="0 0 0" xyz="0 0 0"/>
    </collision>
    <inertial>
      <mass value="0.03"/>
      <inertia ixx="6.75e-07" ixy="0" ixz="0" iyy="6.75e-07" iyz="0" izz="6.75e-07"/>
    </inertial>
  </link>
  <joint name="back_wheel2base_link" type="continuous">
    <parent link="base_link"/>
    <child link="back_wheel"/>
    <origin xyz="-0.0925 0 -0.0475"/>
    <axis xyz="1 1 1"/>
  </joint>
  <gazebo reference="back_wheel">
    <material>Gazebo/Red</material>
  </gazebo>
  <!-- 摄像头安装的z坐标:底盘高度 / 2 + 摄像头高度 / 2  -->
  <!-- 摄像头质量 -->
  <!-- 摄像头关节以及link -->
  <link name="camera">
    <visual>
      <geometry>
        <box size="0.01 0.025 0.025"/>
      </geometry>
      <origin rpy="0.0 0.0 0.0" xyz="0.0 0.0 0.0"/>
      <material name="black"/>
    </visual>
    <collision>
      <geometry>
        <box size="0.01 0.025 0.025"/>
      </geometry>
      <origin rpy="0.0 0.0 0.0" xyz="0.0 0.0 0.0"/>
    </collision>
    <inertial>
      <mass value="0.01"/>
      <inertia ixx="6.041666666666668e-07" ixy="0" ixz="0" iyy="6.041666666666668e-07" iyz="0" izz="1.041666666666667e-06"/>
    </inertial>
  </link>
  <joint name="camera2base_link" type="fixed">
    <parent link="base_link"/>
    <child link="camera"/>
    <origin xyz="0.08 0.0 0.052500000000000005"/>
  </joint>
  <gazebo reference="camera">
    <material>Gazebo/Blue</material>
  </gazebo>
  <!-- 支架安装的z坐标:底盘高度 / 2 + 支架高度 / 2  -->
  <!-- 支架质量 -->
  <link name="support">
    <visual>
      <geometry>
        <cylinder length="0.15" radius="0.01"/>
      </geometry>
      <origin rpy="0.0 0.0 0.0" xyz="0.0 0.0 0.0"/>
      <material name="red">
        <color rgba="0.8 0.2 0.0 0.8"/>
      </material>
    </visual>
    <collision>
      <geometry>
        <cylinder length="0.15" radius="0.01"/>
      </geometry>
      <origin rpy="0.0 0.0 0.0" xyz="0.0 0.0 0.0"/>
    </collision>
    <inertial>
      <mass value="0.02"/>
      <inertia ixx="3.8e-05" ixy="0" ixz="0" iyy="3.8e-05" iyz="0" izz="1.0000000000000002e-06"/>
    </inertial>
  </link>
  <joint name="support2base_link" type="fixed">
    <parent link="base_link"/>
    <child link="support"/>
    <origin xyz="0.0 0.0 0.11499999999999999"/>
  </joint>
  <gazebo reference="support">
    <material>Gazebo/White</material>
  </gazebo>
  <!-- 雷达安装的z坐标:支架高度 / 2 + 雷达高度 / 2  -->
  <!-- 雷达质量 -->
  <!-- 雷达关节以及link -->
  <link name="laser">
    <visual>
      <geometry>
        <cylinder length="0.05" radius="0.03"/>
      </geometry>
      <origin rpy="0.0 0.0 0.0" xyz="0.0 0.0 0.0"/>
      <material name="black"/>
    </visual>
    <collision>
      <geometry>
        <cylinder length="0.05" radius="0.03"/>
      </geometry>
      <origin rpy="0.0 0.0 0.0" xyz="0.0 0.0 0.0"/>
    </collision>
    <inertial>
      <mass value="0.1"/>
      <inertia ixx="4.333333333333333e-05" ixy="0" ixz="0" iyy="4.333333333333333e-05" iyz="0" izz="4.4999999999999996e-05"/>
    </inertial>
  </link>
  <joint name="laser2support" type="fixed">
    <parent link="support"/>
    <child link="laser"/>
    <origin xyz="0.0 0.0 0.1"/>
  </joint>
  <gazebo reference="laser">
    <material>Gazebo/Black</material>
  </gazebo>
</robot>
